Workbook

Sheet Donnees SOMIDA
A1: DONNEES SOMIDA - PARAMETRES ET REFERENTIELS
A2: Paramètre | B2: Valeur | C2: Unité / devise | D2: Commentaire
A3: Exercice | B3: 2019 | C3: année | D3: Exercice
A4: Inflation annuelle | B4: 0.056 | C4: % | D4: Paramètre annuel
A5: Taux USD/MGA | B5: 3650 | C5: MGA/USD | D5: Taux de change
A6: Taux JPY/MGA | B6: 33.5 | C6: MGA/JPY | D6: Taux de change
A7: Augmentation salariale | B7: 0.05 | C7: % | D7: Évolution salariale
A8: TVA | B8: 0.2 | C8: % | D8: Paramètre fiscal
A9: Site principal | B9: FORT DAUPHIN | D9: Administration / export
A10: Site production | B10: AMPANDRANDAVA | D10: Production
A12: MARCHES EXPORT
A13: Pays | B13: Entité représentatrice | C13: Devise | D13: Observation
A14: Japon | B14: GOODEIS | C14: JPY | D14: Marché export
A15: Russie | B15: ELINAR | C15: USD | D15: Marché export
A16: Chine | B16: REPRESENTANT CHINE | C16: USD | D16: Marché export

Sheet Employes
A1: Matricule | B1: Nom | C1: Site | D1: Département | E1: Poste | F1: Salaire base mensuel (MGA) | G1: Prime mensuelle (MGA) | H1: Charges patronales (MGA) | I1: Coût mensuel total (MGA) | J1: Statut
A2: EMP-001 | B2: RABE Hery | C2: FORT DAUPHIN | D2: Direction | E2: Directeur Général | F2: 9827600 | G2: 982760 | H2: 1768810 | I2: =SUM(F2:H2) -> 12579170 | J2: Actif
A3: EMP-002 | B3: RAKOTO Miora | C3: AMPANDRANDAVA | D3: Direction | E3: DAF | F3: 7362800 | G3: 736280 | H3: 1325620 | I3: =SUM(F3:H3) -> 9424700 | J3: Actif
A4: EMP-003 | B4: ANDRIA Fanja | C4: FORT DAUPHIN | D4: Finance | E4: Chef comptable | F4: 4194900 | G4: 503230 | H4: 755240 | I4: =SUM(F4:H4) -> 5453370 | J4: Actif
A5: EMP-004 | B5: RAZAFY Toky | C5: FORT DAUPHIN | D5: Finance | E5: Comptable | F5: 2693900 | G5: 215670 | H5: 485060 | I5: =SUM(F5:H5) -> 3394630 | J5: Actif
A6: EMP-005 | B6: RANDRIA Nirina | C6: AMPANDRANDAVA | D6: Finance | E6: Assistant comptable | F6: 1793300 | G6: 90060 | H6: 323110 | I6: =SUM(F6:H6) -> 2206470 | J6: Actif
A7: EMP-006 | B7: RATSIM Lova | C7: AMPANDRANDAVA | D7: RH | E7: Responsable RH | F7: 3752500 | G7: 300200 | H7: 675450 | I7: =SUM(F7:H7) -> 4728150 | J7: Actif
A8: EMP-007 | B8: RAJAO Aina | C8: AMPANDRANDAVA | D8: Commercial | E8: Responsable commercial export | F8: 4258100 | G8: 340490 | H8: 766300 | I8: =SUM(F8:H8) -> 5364890 | J8: Actif
A9: EMP-008 | B9: RAMAN Tiana | C9: AMPANDRANDAVA | D9: Commercial | E9: Agent export | F9: 2425300 | G9: 121660 | H9: 436870 | I9: =SUM(F9:H9) -> 2983830 | J9: Actif
A10: EMP-010 | B10: RAZAN Mamy | C10: FORT DAUPHIN | D10: Production | E10: Chef d'atelier | F10: 2622800 | G10: 262280 | H10: 472420 | I10: =SUM(F10:H10) -> 3357500 | J10: Actif
A11: EMP-011 | B11: RABARY Lalaina | C11: FORT DAUPHIN | D11: Production | E11: Contrôleur qualité | F11: 2006600 | G11: 160370 | H11: 361030 | I11: =SUM(F11:H11) -> 2528000 | J11: Actif
A12: EMP-012 | B12: RAKOTOMALALA Tahina | C12: TRANOMARO | D12: Production | E12: Opérateur traitement | F12: 1327200 | G12: 105860 | H12: 238580 | I12: =SUM(F12:H12) -> 1671640 | J12: Actif
A13: EMP-013 | B13: ANDRIAMANANA Soa | C13: FORT DAUPHIN | D13: Production | E13: Coupeuse / trieuse | F13: 1011200 | G13: 80580 | H13: 181700 | I13: =SUM(F13:H13) -> 1273480 | J13: Actif
... A91: EMP-092 | B91: RATSIMAHERY Lalaina | C91: AMPANDRANDAVA | D91: Exploitation | E91: Magasinier | F91: 634000 | G91: 51000 | H91: 89000 | I91: =SUM(F91:H91) -> 774000 | J91: Actif

Sheet Production
A1: Site | B1: Produit | C1: Unité | D1: Janvier | E1: Février | F1: Mars | G1: Avril | H1: Mai | I1: Juin | J1: Juillet | K1: Août | L1: Septembre | M1: Octobre | N1: Novembre | O1: Décembre | P1: Total annuel
A2: AMPANDRANDAVA | B2: ABR COUPE | C2: tonnes | D2: 79.03 | E2: 72.16 | F2: 62.76 | G2: 75.42 | H2: 61.92 | I2: 68.28 | J2: 79.25 | K2: 69.92 | L2: 61.42 | M2: 73.12 | N2: 77.97 | O2: 76.24 | P2: =SUM(D2:O2) -> 857.49
A3: AMPANDRANDAVA | B3: FP1 COUPE | C3: tonnes | D3: 59.5 | E3: 49.74 | F3: 47.27 | G3: 54.02 | H3: 54.39 | I3: 48.77 | J3: 54.65 | K3: 52.24 | L3: 60.35 | M3: 56.59 | N3: 49.62 | O3: 54.26 | P3: =SUM(D3:O3) -> 641.4
A4: AMPANDRANDAVA | B4: FP2 COUPE | C4: tonnes | D4: 50.19 | E4: 52.62 | F4: 46.74 | G4: 42.37 | H4: 47.03 | I4: 45.25 | J4: 47.55 | K4: 42.02 | L4: 48.54 | M4: 43.05 | N4: 52.33 | O4: 43.66 | P4: =SUM(D4:O4) -> 561.35
A5: AMPANDRANDAVA | B5: TRA | C5: tonnes | D5: 67.86 | E5: 63.74 | F5: 61.13 | G5: 54.89 | H5: 60.17 | I5: 58.03 | J5: 62.08 | K5: 57.04 | L5: 68.01 | M5: 67.68 | N5: 57.02 | O5: 67.38 | P5: =SUM(D5:O5) -> 745.03
A6: AMPANDRANDAVA | B6: BSA | C6: tonnes | D6: 41.61 | E6: 38.14 | F6: 42.84 | G6: 45.85 | H6: 40.34 | I6: 41.22 | J6: 37.73 | K6: 44.68 | L6: 37.21 | M6: 39.68 | N6: 36.31 | O6: 38.51 | P6: =SUM(D6:O6) -> 484.12
A7: FORT DAUPHIN | B7: ABR COUPE | C7: tonnes | D7: 73.71 | E7: 76.15 | F7: 62.23 | G7: 61.37 | H7: 64.01 | I7: 72.04 | J7: 65.6 | K7: 72.87 | L7: 67.52 | M7: 65.29 | N7: 63.25 | O7: 77.92 | P7: =SUM(D7:O7) -> 821.96
A8: FORT DAUPHIN | B8: FP1 COUPE | C8: tonnes | D8: 60.73 | E8: 58.2 | F8: 60.74 | G8: 54.87 | H8: 51.35 | I8: 46.43 | J8: 56.85 | K8: 47.53 | L8: 52.12 | M8: 50.53 | N8: 61.2 | O8: 60.55 | P8: =SUM(D8:O8) -> 661.1
A9: FORT DAUPHIN | B9: FP2 COUPE | C9: tonnes | D9: 40.68 | E9: 47.63 | F9: 40.08 | G9: 48.48 | H9: 43.25 | I9: 51.36 | J9: 42.25 | K9: 51.43 | L9: 45.63 | M9: 42.29 | N9: 46.16 | O9: 43.31 | P9: =SUM(D9:O9) -> 542.55
A10: FORT DAUPHIN | B10: TRA | C10: tonnes | D10: 61.35 | E10: 54.68 | F10: 57.77 | G10: 66.65 | H10: 67.28 | I10: 63.7 | J10: 64.72 | K10: 56.95 | L10: 63.6 | M10: 55.87 | N10: 64.82 | O10: 55.37 | P10: =SUM(D10:O10) -> 732.76
A11: FORT DAUPHIN | B11: BSA | C11: tonnes | D11: 43.08 | E11: 44.45 | F11: 42.98 | G11: 46.48 | H11: 38.77 | I11: 38.65 | J11: 43.15 | K11: 41.29 | L11: 43.77 | M11: 34.92 | N11: 38.04 | O11: 36.36 | P11: =SUM(D11:O11) -> 491.94

Sheet Charges
A1: Catégorie | B1: Nature | C1: Site | D1: Unité | E1: Janvier | F1: Février | G1: Mars | H1: Avril | I1: Mai | J1: Juin | K1: Juillet | L1: Août | M1: Septembre | N1: Octobre | O1: Novembre | P1: Décembre | Q1: Total annuel
A2: PRODUCTION | B2: Matières et consommables | C2: AMPANDRANDAVA | D2: MGA | E2: 105714070 | F2: 112374570 | G2: 123371710 | H2: 104337310 | I2: 123330900 | J2: 101935680 | K2: 110213180 | L2: 113386350 | M2: 101757040 | N2: 101895640 | O2: 117566680 | P2: 105308280 | Q2: 1321191410
A3: PRODUCTION | B3: Énergie / électricité | C3: AMPANDRANDAVA | D3: MGA | E3: 38419920 | F3: 38788750 | G3: 41616190 | H3: 37432780 | I3: 32835880 | J3: 33964700 | K3: 39112150 | L3: 36784440 | M3: 35215180 | N3: 40718370 | O3: 37898630 | P3: 40904710 | Q3: 453691700
A4: PRODUCTION | B4: Traitement mica | C4: AMPANDRANDAVA | D4: MGA | E4: 65768010 | F4: 66314710 | G4: 60040750 | H4: 61606930 | I4: 69728890 | J4: 65630950 | K4: 63505750 | L4: 61305090 | M4: 58058770 | N4: 63575050 | O4: 70915460 | P4: 64268050 | Q4: 770718410
A5: PRODUCTION | B5: Maintenance équipements | C5: AMPANDRANDAVA | D5: MGA | E5: 22896720 | F5: 24391290 | G5: 23693670 | H5: 21724780 | I5: 26211570 | J5: 24289650 | K5: 23418780 | L5: 25734940 | M5: 22186010 | N5: 27087830 | O5: 25816560 | P5: 24532200 | Q5: 291984000
A6: PRODUCTION | B6: Emballages | C6: FORT DAUPHIN | D6: MGA | E6: 17234140 | F6: 18583180 | G6: 19724320 | H6: 17336550 | I6: 19207650 | J6: 17710000 | K6: 18631690 | L6: 17660720 | M6: 17617600 | N6: 16520350 | O6: 17237220 | P6: 19622680 | Q6: 217086100
A7: ADMINISTRATION | B7: Télécommunications / Internet | C7: FORT DAUPHIN | D7: MGA | E7: 6165390 | F7: 5364590 | G7: 6431810 | H7: 6247010 | I7: 5848150 | J7: 6502650 | K7: 5225990 | L7: 5779620 | M7: 5462380 | N7: 5159770 | O7: 5370750 | P7: 5274500 | Q7: 68832610
A8: ADMINISTRATION | B8: Assurances | C8: FORT DAUPHIN | D8: MGA | E8: 9718170 | F8: 9940700 | G8: 10686060 | H8: 11075680 | I8: 9121420 | J8: 10946320 | K8: 9935310 | L8: 8826510 | M8: 10494330 | N8: 10883950 | O8: 10112410 | P8: 10597510 | Q8: 122338370
A9: ADMINISTRATION | B9: Honoraires et conseil | C9: FORT DAUPHIN | D9: MGA | E9: 13228600 | F9: 11465300 | G9: 13415710 | H9: 12407780 | I9: 12934460 | J9: 13793010 | K9: 12366970 | L9: 12062050 | M9: 12236070 | N9: 11522280 | O9: 10977890 | P9: 12994520 | Q9: 149404640
A10: LOGISTIQUE | B10: Transport interne | C10: FORT DAUPHIN | D10: MGA | E10: 29032080 | F10: 30576700 | G10: 29592640 | H10: 26303200 | I10: 27709220 | J10: 31649310 | K10: 26604270 | L10: 30344160 | M10: 29665790 | N10: 28391440 | O10: 28142730 | P10: 31546900 | Q10: 349558440
A11: LOGISTIQUE | B11: Magasinage / manutention | C11: FORT DAUPHIN | D11: MGA | E11: 17486700 | F11: 16920750 | G11: 18073440 | H11: 18255160 | I11: 18312140 | J11: 16068360 | K11: 16631230 | L11: 18399920 | M11: 17027010 | N11: 15996750 | O11: 15380750 | P11: 15965180 | Q11: 204517390
A12: FISCAL | B12: Impôts et taxes | C12: FORT DAUPHIN | D12: MGA | E12: 21021770 | F12: 23114630 | G12: 21988890 | H12: 20524350 | I12: 22211420 | J12: 19276950 | K12: 22463980 | L12: 19698140 | M12: 18851910 | N12: 19140660 | O12: 19487160 | P12: 22945230 | Q12: 250725090
A13: FINANCE | B13: Frais bancaires | C13: FORT DAUPHIN | D13: MGA | E13: 8032640 | F13: 7614530 | G13: 9497950 | H13: 9240000 | I13: 7983360 | J13: 9360120 | K13: 9524900 | L13: 7629160 | M13: 8237460 | N13: 7813960 | O13: 8216670 | P13: 9113720 | Q13: 102264470
A14: SECURITE | B14: Gardiennage / sécurité | C14: AMPANDRANDAVA | D14: MGA | E14: 12497870 | F14: 11829510 | G14: 12356190 | H14: 11414480 | I14: 11957330 | J14: 10864700 | K14: 10267950 | L14: 12391610 | M14: 12367740 | N14: 11181170 | O14: 11742500 | P14: 11493790 | Q14: 140364840

Sheet Exportations
A1: SOMIDA — TABLEAU DE BORD DES EXPORTATIONS 2019
A2: Pilotage DAF • Japon / Russie / Chine • Suivi mensuel des volumes, devises et chiffre d’affaires
A4: VOLUME EXPORTÉ (t) | D4: CA EXPORT (MGA) | G4: CA JAPON (MGA) | J4: CA RUSSIE (MGA) | M4: CA CHINE (MGA) | P4: MARCHÉS / DEVISES
A5: =SUMIF($E$10:$E$54,"Quantité exportée",$S$10:$S$54) -> 3094.92 | D5: =SUMIF($E$10:$E$54,"Chiffre d'affaires MGA",$S$10:$S$54) -> 16055910530 | G5: =SUMIFS($S$10:$S$54,$A$10:$A$54,"Japon",$E$10:$E$54,"Chiffre d'affaires MGA") -> 5951042845 | J5: =SUMIFS($S$10:$S$54,$A$10:$A$54,"Russie",$E$10:$E$54,"Chiffre d'affaires MGA") -> 5086859365 | M5: =SUMIFS($S$10:$S$54,$A$10:$A$54,"Chine",$E$10:$E$54,"Chiffre d'affaires MGA") -> 5018008320 | P5: 3 pays • JPY / USD
A7: DÉTAIL MENSUEL DES EXPORTATIONS PAR MARCHÉ, REPRÉSENTANT ET PRODUIT
A9: Pays | B9: Entité représentatrice | C9: Produit | D9: Devise | E9: Indicateur | F9: Unité | G9: Janvier | H9: Février | I9: Mars | J9: Avril | K9: Mai | L9: Juin | M9: Juillet | N9: Août | O9: Septembre | P9: Octobre | Q9: Novembre | R9: Décembre | S9: Total annuel
A10: Japon | B10: GOODEIS | C10: ABR COUPE | D10: JPY | E10: Quantité exportée | F10: tonnes | G10: 26.98 | H10: 20.36 | I10: 16.55 | J10: 18.41 | K10: 16.68 | L10: 25.44 | M10: 21.5 | N10: 25.5 | O10: 16.9 | P10: 15.88 | Q10: 16.83 | R10: 25.95 | S10: 246.98
A11: Japon | B11: GOODEIS | C11: ABR COUPE | D11: JPY | E11: Chiffre d'affaires devise | F11: JPY | G11: 4991300 | H11: 3766600 | I11: 3061750 | J11: 3405850 | K11: 3085800 | L11: 4706400 | M11: 3977500 | N11: 4717500 | O11: 3126500 | P11: 2937800 | Q11: 3113550 | R11: 4800750 | S11: 45691300
A12: Japon | B12: GOODEIS | C12: ABR COUPE | D12: JPY | E12: Chiffre d'affaires MGA | F12: MGA | G12: =IF($D12="USD",G11*'Donnees SOMIDA'!$B$5,IF($D12="JPY",G11*'Donnees SOMIDA'!$B$6,0)) -> 167208550 | H12: =IF($D12="USD",H11*'Donnees SOMIDA'!$B$5,IF($D12="JPY",H11*'Donnees SOMIDA'!$B$6,0)) -> 126181100 | I12: =IF($D12="USD",I11*'Donnees SOMIDA'!$B$5,IF($D12="JPY",I11*'Donnees SOMIDA'!$B$6,0)) -> 102568625 | J12: =IF($D12="USD",J11*'Donnees SOMIDA'!$B$5,IF($D12="JPY",J11*'Donnees SOMIDA'!$B$6,0)) -> 114095975 | K12: =IF($D12="USD",K11*'Donnees SOMIDA'!$B$5,IF($D12="JPY",K11*'Donnees SOMIDA'!$B$6,0)) -> 103374300 | L12: =IF($D12="USD",L11*'Donnees SOMIDA'!$B$5,IF($D12="JPY",L11*'Donnees SOMIDA'!$B$6,0)) -> 157664400 | M12: =IF($D12="USD",M11*'Donnees SOMIDA'!$B$5,IF($D12="JPY",M11*'Donnees SOMIDA'!$B$6,0)) -> 133246250 | N12: =IF($D12="USD",N11*'Donnees SOMIDA'!$B$5,IF($D12="JPY",N11*'Donnees SOMIDA'!$B$6,0)) -> 158036250 | ... R12: =IF($D12="USD",R11*'Donnees SOMIDA'!$B$5,IF($D12="JPY",R11*'Donnees SOMIDA'!$B$6,0)) -> 160825125 | S12: =SUM(G12:R12) -> 1530658550
A13: Japon | B13: GOODEIS | C13: FP1 COUPE | D13: JPY | E13: Quantité exportée | F13: tonnes | G13: 18.23 | H13: 14.24 | I13: 18.92 | J13: 14.44 | K13: 20.13 | L13: 21.29 | M13: 17.77 | N13: 19.57 | O13: 16.22 | P13: 17.27 | Q13: 15.9 | R13: 14.77 | S13: 208.75
A14: Japon | B14: GOODEIS | C14: FP1 COUPE | D14: JPY | E14: Chiffre d'affaires devise | F14: JPY | G14: 3117330 | H14: 2435040 | I14: 3235320 | J14: 2469240 | K14: 3442230 | L14: 3640590 | M14: 3038670 | N14: 3346470 | O14: 2773620 | P14: 2953170 | Q14: 2718900 | R14: 2525670 | S14: 35696250
A15: Japon | B15: GOODEIS | C15: FP1 COUPE | D15: JPY | E15: Chiffre d'affaires MGA | F15: MGA | G15: =IF($D15="USD",G14*'Donnees SOMIDA'!$B$5,IF($D15="JPY",G14*'Donnees SOMIDA'!$B$6,0)) -> 104430555 | H15: =IF($D15="USD",H14*'Donnees SOMIDA'!$B$5,IF($D15="JPY",H14*'Donnees SOMIDA'!$B$6,0)) -> 81573840 | I15: =IF($D15="USD",I14*'Donnees SOMIDA'!$B$5,IF($D15="JPY",I14*'Donnees SOMIDA'!$B$6,0)) -> 108383220 | J15: =IF($D15="USD",J14*'Donnees SOMIDA'!$B$5,IF($D15="JPY",J14*'Donnees SOMIDA'!$B$6,0)) -> 82719540 | K15: =IF($D15="USD",K14*'Donnees SOMIDA'!$B$5,IF($D15="JPY",K14*'Donnees SOMIDA'!$B$6,0)) -> 115314705 | L15: =IF($D15="USD",L14*'Donnees SOMIDA'!$B$5,IF($D15="JPY",L14*'Donnees SOMIDA'!$B$6,0)) -> 121959765 | M15: =IF($D15="USD",M14*'Donnees SOMIDA'!$B$5,IF($D15="JPY",M14*'Donnees SOMIDA'!$B$6,0)) -> 101795445 | N15: =IF($D15="USD",N14*'Donnees SOMIDA'!$B$5,IF($D15="JPY",N14*'Donnees SOMIDA'!$B$6,0)) -> 112106745 | ... R15: =IF($D15="USD",R14*'Donnees SOMIDA'!$B$5,IF($D15="JPY",R14*'Donnees SOMIDA'!$B$6,0)) -> 84609945 | S15: =SUM(G15:R15) -> 1195824375
A16: Japon | B16: GOODEIS | C16: FP2 COUPE | D16: JPY | E16: Quantité exportée | F16: tonnes | G16: 17.69 | H16: 18.26 | I16: 16.81 | J16: 12.01 | K16: 13.83 | L16: 12.45 | M16: 14.83 | N16: 16.64 | O16: 19.18 | P16: 11.88 | Q16: 14.27 | R16: 18.46 | S16: 186.31
A17: Japon | B17: GOODEIS | C17: FP2 COUPE | D17: JPY | E17: Chiffre d'affaires devise | F17: JPY | G17: 2918850 | H17: 3012900 | I17: 2773650 | J17: 1981650 | K17: 2281950 | L17: 2054250 | M17: 2446950 | N17: 2745600 | O17: 3164700 | P17: 1960200 | Q17: 2354550 | R17: 3045900 | S17: 30741150
A18: Japon | B18: GOODEIS | C18: FP2 COUPE | D18: JPY | E18: Chiffre d'affaires MGA | F18: MGA | G18: =IF($D18="USD",G17*'Donnees SOMIDA'!$B$5,IF($D18="JPY",G17*'Donnees SOMIDA'!$B$6,0)) -> 97781475 | H18: =IF($D18="USD",H17*'Donnees SOMIDA'!$B$5,IF($D18="JPY",H17*'Donnees SOMIDA'!$B$6,0)) -> 100932150 | I18: =IF($D18="USD",I17*'Donnees SOMIDA'!$B$5,IF($D18="JPY",I17*'Donnees SOMIDA'!$B$6,0)) -> 92917275 | J18: =IF($D18="USD",J17*'Donnees SOMIDA'!$B$5,IF($D18="JPY",J17*'Donnees SOMIDA'!$B$6,0)) -> 66385275 | K18: =IF($D18="USD",K17*'Donnees SOMIDA'!$B$5,IF($D18="JPY",K17*'Donnees SOMIDA'!$B$6,0)) -> 76445325 | L18: =IF($D18="USD",L17*'Donnees SOMIDA'!$B$5,IF($D18="JPY",L17*'Donnees SOMIDA'!$B$6,0)) -> 68817375 | M18: =IF($D18="USD",M17*'Donnees SOMIDA'!$B$5,IF($D18="JPY",M17*'Donnees SOMIDA'!$B$6,0)) -> 81972825 | N18: =IF($D18="USD",N17*'Donnees SOMIDA'!$B$5,IF($D18="JPY",N17*'Donnees SOMIDA'!$B$6,0)) -> 91977600 | ... R18: =IF($D18="USD",R17*'Donnees SOMIDA'!$B$5,IF($D18="JPY",R17*'Donnees SOMIDA'!$B$6,0)) -> 102037650 | S18: =SUM(G18:R18) -> 1029828525
A19: Japon | B19: GOODEIS | C19: TRA | D19: JPY | E19: Quantité exportée | F19: tonnes | G19: 17.08 | H19: 19.28 | I19: 23.69 | J19: 16.17 | K19: 18.62 | L19: 24.79 | M19: 21.53 | N19: 22.55 | O19: 20.48 | P19: 21.28 | Q19: 18.05 | R19: 21.47 | S19: 244.99
A20: Japon | B20: GOODEIS | C20: TRA | D20: JPY | E20: Chiffre d'affaires devise | F20: JPY | G20: 3040240 | H20: 3431840 | I20: 4216820 | J20: 2878260 | K20: 3314360 | L20: 4412620 | M20: 3832340 | N20: 4013900 | O20: 3645440 | P20: 3787840 | Q20: 3212900 | R20: 3821660 | S20: 43608220
A21: Japon | B21: GOODEIS | C21: TRA | D21: JPY | E21: Chiffre d'affaires MGA | F21: MGA | G21: =IF($D21="USD",G20*'Donnees SOMIDA'!$B$5,IF($D21="JPY",G20*'Donnees SOMIDA'!$B$6,0)) -> 101848040 | H21: =IF($D21="USD",H20*'Donnees SOMIDA'!$B$5,IF($D21="JPY",H20*'Donnees SOMIDA'!$B$6,0)) -> 114966640 | I21: =IF($D21="USD",I20*'Donnees SOMIDA'!$B$5,IF($D21="JPY",I20*'Donnees SOMIDA'!$B$6,0)) -> 141263470 | J21: =IF($D21="USD",J20*'Donnees SOMIDA'!$B$5,IF($D21="JPY",J20*'Donnees SOMIDA'!$B$6,0)) -> 96421710 | K21: =IF($D21="USD",K20*'Donnees SOMIDA'!$B$5,IF($D21="JPY",K20*'Donnees SOMIDA'!$B$6,0)) -> 111031060 | L21: =IF($D21="USD",L20*'Donnees SOMIDA'!$B$5,IF($D21="JPY",L20*'Donnees SOMIDA'!$B$6,0)) -> 147822770 | M21: =IF($D21="USD",M20*'Donnees SOMIDA'!$B$5,IF($D21="JPY",M20*'Donnees SOMIDA'!$B$6,0)) -> 128383390 | N21: =IF($D21="USD",N20*'Donnees SOMIDA'!$B$5,IF($D21="JPY",N20*'Donnees SOMIDA'!$B$6,0)) -> 134465650 | ... R21: =IF($D21="USD",R20*'Donnees SOMIDA'!$B$5,IF($D21="JPY",R20*'Donnees SOMIDA'!$B$6,0)) -> 128025610 | S21: =SUM(G21:R21) -> 1460875370
A22: Japon | B22: GOODEIS | C22: BSA | D22: JPY | E22: Quantité exportée | F22: tonnes | G22: 11.07 | H22: 10.97 | I22: 9.46 | J22: 9.93 | K22: 12.15 | L22: 14.06 | M22: 9.35 | N22: 12.71 | O22: 11.77 | P22: 13.79 | Q22: 12.49 | R22: 13.58 | S22: 141.33
A23: Japon | B23: GOODEIS | C23: BSA | D23: JPY | E23: Chiffre d'affaires devise | F23: JPY | G23: 1715850 | H23: 1700350 | I23: 1466300 | J23: 1539150 | K23: 1883250 | L23: 2179300 | M23: 1449250 | N23: 1970050 | O23: 1824350 | P23: 2137450 | Q23: 1935950 | R23: 2104900 | S23: 21906150
A24: Japon | B24: GOODEIS | C24: BSA | D24: JPY | E24: Chiffre d'affaires MGA | F24: MGA | G24: =IF($D24="USD",G23*'Donnees SOMIDA'!$B$5,IF($D24="JPY",G23*'Donnees SOMIDA'!$B$6,0)) -> 57480975 | H24: =IF($D24="USD",H23*'Donnees SOMIDA'!$B$5,IF($D24="JPY",H23*'Donnees SOMIDA'!$B$6,0)) -> 56961725 | I24: =IF($D24="USD",I23*'Donnees SOMIDA'!$B$5,IF($D24="JPY",I23*'Donnees SOMIDA'!$B$6,0)) -> 49121050 | J24: =IF($D24="USD",J23*'Donnees SOMIDA'!$B$5,IF($D24="JPY",J23*'Donnees SOMIDA'!$B$6,0)) -> 51561525 | K24: =IF($D24="USD",K23*'Donnees SOMIDA'!$B$5,IF($D24="JPY",K23*'Donnees SOMIDA'!$B$6,0)) -> 63088875 | L24: =IF($D24="USD",L23*'Donnees SOMIDA'!$B$5,IF($D24="JPY",L23*'Donnees SOMIDA'!$B$6,0)) -> 73006550 | M24: =IF($D24="USD",M23*'Donnees SOMIDA'!$B$5,IF($D24="JPY",M23*'Donnees SOMIDA'!$B$6,0)) -> 48549875 | N24: =IF($D24="USD",N23*'Donnees SOMIDA'!$B$5,IF($D24="JPY",N23*'Donnees SOMIDA'!$B$6,0)) -> 65996675 | ... R24: =IF($D24="USD",R23*'Donnees SOMIDA'!$B$5,IF($D24="JPY",R23*'Donnees SOMIDA'!$B$6,0)) -> 70514150 | S24: =SUM(G24:R24) -> 733856025
A25: Russie | B25: ELINAR | C25: ABR COUPE | D25: USD | E25: Quantité exportée | F25: tonnes | G25: 27.77 | H25: 21.84 | I25: 27.29 | J25: 19.78 | K25: 23.42 | L25: 18.77 | M25: 17.97 | N25: 18.58 | O25: 25.58 | P25: 27.23 | Q25: 16.17 | R25: 21.51 | S25: 265.91
A26: Russie | B26: ELINAR | C26: ABR COUPE | D26: USD | E26: Chiffre d'affaires devise | F26: USD | G26: 40266.5 | H26: 31668 | I26: 39570.5 | J26: 28681 | K26: 33959 | L26: 27216.5 | M26: 26056.5 | N26: 26941 | O26: 37091 | P26: 39483.5 | Q26: 23446.5 | R26: 31189.5 | S26: 385569.5
A27: Russie | B27: ELINAR | C27: ABR COUPE | D27: USD | E27: Chiffre d'affaires MGA | F27: MGA | G27: =IF($D27="USD",G26*'Donnees SOMIDA'!$B$5,IF($D27="JPY",G26*'Donnees SOMIDA'!$B$6,0)) -> 146972725 | H27: =IF($D27="USD",H26*'Donnees SOMIDA'!$B$5,IF($D27="JPY",H26*'Donnees SOMIDA'!$B$6,0)) -> 115588200 | I27: =IF($D27="USD",I26*'Donnees SOMIDA'!$B$5,IF($D27="JPY",I26*'Donnees SOMIDA'!$B$6,0)) -> 144432325 | J27: =IF($D27="USD",J26*'Donnees SOMIDA'!$B$5,IF($D27="JPY",J26*'Donnees SOMIDA'!$B$6,0)) -> 104685650 | K27: =IF($D27="USD",K26*'Donnees SOMIDA'!$B$5,IF($D27="JPY",K26*'Donnees SOMIDA'!$B$6,0)) -> 123950350 | L27: =IF($D27="USD",L26*'Donnees SOMIDA'!$B$5,IF($D27="JPY",L26*'Donnees SOMIDA'!$B$6,0)) -> 99340225 | M27: =IF($D27="USD",M26*'Donnees SOMIDA'!$B$5,IF($D27="JPY",M26*'Donnees SOMIDA'!$B$6,0)) -> 95106225 | N27: =IF($D27="USD",N26*'Donnees SOMIDA'!$B$5,IF($D27="JPY",N26*'Donnees SOMIDA'!$B$6,0)) -> 98334650 | ... R27: =IF($D27="USD",R26*'Donnees SOMIDA'!$B$5,IF($D27="JPY",R26*'Donnees SOMIDA'!$B$6,0)) -> 113841675 | S27: =SUM(G27:R27) -> 1407328675
A28: Russie | B28: ELINAR | C28: FP1 COUPE | D28: USD | E28: Quantité exportée | F28: tonnes | G28: 17.13 | H28: 12.66 | I28: 19.32 | J28: 13.79 | K28: 20.93 | L28: 17.73 | M28: 14.43 | N28: 17.65 | O28: 18.74 | P28: 16.4 | Q28: 18.21 | R28: 19.73 | S28: 206.72
A29: Russie | B29: ELINAR | C29: FP1 COUPE | D29: USD | E29: Chiffre d'affaires devise | F29: USD | G29: 22611.6 | H29: 16711.2 | I29: 25502.4 | J29: 18202.8 | K29: 27627.6 | L29: 23403.6 | M29: 19047.6 | N29: 23298 | O29: 24736.8 | P29: 21648 | Q29: 24037.2 | R29: 26043.6 | S29: 272870.4
A30: Russie | B30: ELINAR | C30: FP1 COUPE | D30: USD | E30: Chiffre d'affaires MGA | F30: MGA | G30: =IF($D30="USD",G29*'Donnees SOMIDA'!$B$5,IF($D30="JPY",G29*'Donnees SOMIDA'!$B$6,0)) -> 82532340 | H30: =IF($D30="USD",H29*'Donnees SOMIDA'!$B$5,IF($D30="JPY",H29*'Donnees SOMIDA'!$B$6,0)) -> 60995880 | I30: =IF($D30="USD",I29*'Donnees SOMIDA'!$B$5,IF($D30="JPY",I29*'Donnees SOMIDA'!$B$6,0)) -> 93083760 | J30: =IF($D30="USD",J29*'Donnees SOMIDA'!$B$5,IF($D30="JPY",J29*'Donnees SOMIDA'!$B$6,0)) -> 66440220 | K30: =IF($D30="USD",K29*'Donnees SOMIDA'!$B$5,IF($D30="JPY",K29*'Donnees SOMIDA'!$B$6,0)) -> 100840740 | L30: =IF($D30="USD",L29*'Donnees SOMIDA'!$B$5,IF($D30="JPY",L29*'Donnees SOMIDA'!$B$6,0)) -> 85423140 | M30: =IF($D30="USD",M29*'Donnees SOMIDA'!$B$5,IF($D30="JPY",M29*'Donnees SOMIDA'!$B$6,0)) -> 69523740 | N30: =IF($D30="USD",N29*'Donnees SOMIDA'!$B$5,IF($D30="JPY",N29*'Donnees SOMIDA'!$B$6,0)) -> 85037700 | ... R30: =IF($D30="USD",R29*'Donnees SOMIDA'!$B$5,IF($D30="JPY",R29*'Donnees SOMIDA'!$B$6,0)) -> 95059140 | S30: =SUM(G30:R30) -> 995976960
A31: Russie | B31: ELINAR | C31: FP2 COUPE | D31: USD | E31: Quantité exportée | F31: tonnes | G31: 14.67 | H31: 15.16 | I31: 16.67 | J31: 14.66 | K31: 15.19 | L31: 13.32 | M31: 18.69 | N31: 18.89 | O31: 12.49 | P31: 14.8 | Q31: 12.51 | R31: 13.17 | S31: 180.22
A32: Russie | B32: ELINAR | C32: FP2 COUPE | D32: USD | E32: Chiffre d'affaires devise | F32: USD | G32: 18630.9 | H32: 19253.2 | I32: 21170.9 | J32: 18618.2 | K32: 19291.3 | L32: 16916.4 | M32: 23736.3 | N32: 23990.3 | O32: 15862.3 | P32: 18796 | Q32: 15887.7 | R32: 16725.9 | S32: 228879.4
A33: Russie | B33: ELINAR | C33: FP2 COUPE | D33: USD | E33: Chiffre d'affaires MGA | F33: MGA | G33: =IF($D33="USD",G32*'Donnees SOMIDA'!$B$5,IF($D33="JPY",G32*'Donnees SOMIDA'!$B$6,0)) -> 68002785 | H33: =IF($D33="USD",H32*'Donnees SOMIDA'!$B$5,IF($D33="JPY",H32*'Donnees SOMIDA'!$B$6,0)) -> 70274180 | I33: =IF($D33="USD",I32*'Donnees SOMIDA'!$B$5,IF($D33="JPY",I32*'Donnees SOMIDA'!$B$6,0)) -> 77273785 | J33: =IF($D33="USD",J32*'Donnees SOMIDA'!$B$5,IF($D33="JPY",J32*'Donnees SOMIDA'!$B$6,0)) -> 67956430 | K33: =IF($D33="USD",K32*'Donnees SOMIDA'!$B$5,IF($D33="JPY",K32*'Donnees SOMIDA'!$B$6,0)) -> 70413245 | L33: =IF($D33="USD",L32*'Donnees SOMIDA'!$B$5,IF($D33="JPY",L32*'Donnees SOMIDA'!$B$6,0)) -> 61744860 | M33: =IF($D33="USD",M32*'Donnees SOMIDA'!$B$5,IF($D33="JPY",M32*'Donnees SOMIDA'!$B$6,0)) -> 86637495 | N33: =IF($D33="USD",N32*'Donnees SOMIDA'!$B$5,IF($D33="JPY",N32*'Donnees SOMIDA'!$B$6,0)) -> 87564595 | ... R33: =IF($D33="USD",R32*'Donnees SOMIDA'!$B$5,IF($D33="JPY",R32*'Donnees SOMIDA'!$B$6,0)) -> 61049535 | S33: =SUM(G33:R33) -> 835409810
A34: Russie | B34: ELINAR | C34: TRA | D34: USD | E34: Quantité exportée | F34: tonnes | G34: 19.18 | H34: 25.19 | I34: 16.03 | J34: 21.7 | K34: 19.09 | L34: 17.42 | M34: 22.46 | N34: 23.18 | O34: 16.12 | P34: 15.33 | Q34: 25.26 | R34: 20.56 | S34: 241.52
A35: Russie | B35: ELINAR | C35: TRA | D35: USD | E35: Chiffre d'affaires devise | F35: USD | G35: 26660.2 | H35: 35014.1 | I35: 22281.7 | J35: 30163 | K35: 26535.1 | L35: 24213.8 | M35: 31219.4 | N35: 32220.2 | O35: 22406.8 | P35: 21308.7 | Q35: 35111.4 | R35: 28578.4 | S35: 335712.8
A36: Russie | B36: ELINAR | C36: TRA | D36: USD | E36: Chiffre d'affaires MGA | F36: MGA | G36: =IF($D36="USD",G35*'Donnees SOMIDA'!$B$5,IF($D36="JPY",G35*'Donnees SOMIDA'!$B$6,0)) -> 97309730 | H36: =IF($D36="USD",H35*'Donnees SOMIDA'!$B$5,IF($D36="JPY",H35*'Donnees SOMIDA'!$B$6,0)) -> 127801465 | I36: =IF($D36="USD",I35*'Donnees SOMIDA'!$B$5,IF($D36="JPY",I35*'Donnees SOMIDA'!$B$6,0)) -> 81328205 | J36: =IF($D36="USD",J35*'Donnees SOMIDA'!$B$5,IF($D36="JPY",J35*'Donnees SOMIDA'!$B$6,0)) -> 110094950 | K36: =IF($D36="USD",K35*'Donnees SOMIDA'!$B$5,IF($D36="JPY",K35*'Donnees SOMIDA'!$B$6,0)) -> 96853115 | L36: =IF($D36="USD",L35*'Donnees SOMIDA'!$B$5,IF($D36="JPY",L35*'Donnees SOMIDA'!$B$6,0)) -> 88380370 | M36: =IF($D36="USD",M35*'Donnees SOMIDA'!$B$5,IF($D36="JPY",M35*'Donnees SOMIDA'!$B$6,0)) -> 113950810 | N36: =IF($D36="USD",N35*'Donnees SOMIDA'!$B$5,IF($D36="JPY",N35*'Donnees SOMIDA'!$B$6,0)) -> 117603730 | ... R36: =IF($D36="USD",R35*'Donnees SOMIDA'!$B$5,IF($D36="JPY",R35*'Donnees SOMIDA'!$B$6,0)) -> 104311160 | S36: =SUM(G36:R36) -> 1225351720
A37: Russie | B37: ELINAR | C37: BSA | D37: USD | E37: Quantité exportée | F37: tonnes | G37: 12.62 | H37: 11.98 | I37: 10.11 | J37: 14.04 | K37: 13.66 | L37: 9.69 | M37: 10.37 | N37: 9.66 | O37: 15.09 | P37: 12.24 | Q37: 10.73 | R37: 14.41 | S37: 144.6
A38: Russie | B38: ELINAR | C38: BSA | D38: USD | E38: Chiffre d'affaires devise | F38: USD | G38: 14891.6 | H38: 14136.4 | I38: 11929.8 | J38: 16567.2 | K38: 16118.8 | L38: 11434.2 | M38: 12236.6 | N38: 11398.8 | O38: 17806.2 | P38: 14443.2 | Q38: 12661.4 | R38: 17003.8 | S38: 170628
A39: Russie | B39: ELINAR | C39: BSA | D39: USD | E39: Chiffre d'affaires MGA | F39: MGA | G39: =IF($D39="USD",G38*'Donnees SOMIDA'!$B$5,IF($D39="JPY",G38*'Donnees SOMIDA'!$B$6,0)) -> 54354340 | H39: =IF($D39="USD",H38*'Donnees SOMIDA'!$B$5,IF($D39="JPY",H38*'Donnees SOMIDA'!$B$6,0)) -> 51597860 | I39: =IF($D39="USD",I38*'Donnees SOMIDA'!$B$5,IF($D39="JPY",I38*'Donnees SOMIDA'!$B$6,0)) -> 43543770 | J39: =IF($D39="USD",J38*'Donnees SOMIDA'!$B$5,IF($D39="JPY",J38*'Donnees SOMIDA'!$B$6,0)) -> 60470280 | K39: =IF($D39="USD",K38*'Donnees SOMIDA'!$B$5,IF($D39="JPY",K38*'Donnees SOMIDA'!$B$6,0)) -> 58833620 | L39: =IF($D39="USD",L38*'Donnees SOMIDA'!$B$5,IF($D39="JPY",L38*'Donnees SOMIDA'!$B$6,0)) -> 41734830 | M39: =IF($D39="USD",M38*'Donnees SOMIDA'!$B$5,IF($D39="JPY",M38*'Donnees SOMIDA'!$B$6,0)) -> 44663590 | N39: =IF($D39="USD",N38*'Donnees SOMIDA'!$B$5,IF($D39="JPY",N38*'Donnees SOMIDA'!$B$6,0)) -> 41605620 | ... R39: =IF($D39="USD",R38*'Donnees SOMIDA'!$B$5,IF($D39="JPY",R38*'Donnees SOMIDA'!$B$6,0)) -> 62063870 | S39: =SUM(G39:R39) -> 622792200
A40: Chine | B40: REPRESENTANT CHINE - A VALIDER | C40: ABR COUPE | D40: USD | E40: Quantité exportée | F40: tonnes | G40: 19.87 | H40: 24.57 | I40: 21.9 | J40: 18.13 | K40: 18.81 | L40: 20.63 | M40: 16.81 | N40: 24.79 | O40: 16.37 | P40: 20.94 | Q40: 17.91 | R40: 18.35 | S40: 239.08
A41: Chine | B41: REPRESENTANT CHINE - A VALIDER | C41: ABR COUPE | D41: USD | E41: Chiffre d'affaires devise | F41: USD | G41: 28811.5 | H41: 35626.5 | I41: 31755 | J41: 26288.5 | K41: 27274.5 | L41: 29913.5 | M41: 24374.5 | N41: 35945.5 | O41: 23736.5 | P41: 30363 | Q41: 25969.5 | R41: 26607.5 | S41: 346666
A42: Chine | B42: REPRESENTANT CHINE - A VALIDER | C42: ABR COUPE | D42: USD | E42: Chiffre d'affaires MGA | F42: MGA | G42: =IF($D42="USD",G41*'Donnees SOMIDA'!$B$5,IF($D42="JPY",G41*'Donnees SOMIDA'!$B$6,0)) -> 105161975 | H42: =IF($D42="USD",H41*'Donnees SOMIDA'!$B$5,IF($D42="JPY",H41*'Donnees SOMIDA'!$B$6,0)) -> 130036725 | I42: =IF($D42="USD",I41*'Donnees SOMIDA'!$B$5,IF($D42="JPY",I41*'Donnees SOMIDA'!$B$6,0)) -> 115905750 | J42: =IF($D42="USD",J41*'Donnees SOMIDA'!$B$5,IF($D42="JPY",J41*'Donnees SOMIDA'!$B$6,0)) -> 95953025 | K42: =IF($D42="USD",K41*'Donnees SOMIDA'!$B$5,IF($D42="JPY",K41*'Donnees SOMIDA'!$B$6,0)) -> 99551925 | L42: =IF($D42="USD",L41*'Donnees SOMIDA'!$B$5,IF($D42="JPY",L41*'Donnees SOMIDA'!$B$6,0)) -> 109184275 | M42: =IF($D42="USD",M41*'Donnees SOMIDA'!$B$5,IF($D42="JPY",M41*'Donnees SOMIDA'!$B$6,0)) -> 88966925 | N42: =IF($D42="USD",N41*'Donnees SOMIDA'!$B$5,IF($D42="JPY",N41*'Donnees SOMIDA'!$B$6,0)) -> 131201075 | ... R42: =IF($D42="USD",R41*'Donnees SOMIDA'!$B$5,IF($D42="JPY",R41*'Donnees SOMIDA'!$B$6,0)) -> 97117375 | S42: =SUM(G42:R42) -> 1265330900
A43: Chine | B43: REPRESENTANT CHINE - A VALIDER | C43: FP1 COUPE | D43: USD | E43: Quantité exportée | F43: tonnes | G43: 12.67 | H43: 21.44 | I43: 17.88 | J43: 18.28 | K43: 21.06 | L43: 20 | M43: 14.02 | N43: 13.37 | O43: 15.46 | P43: 19.14 | Q43: 17.55 | R43: 21.56 | S43: 212.43
...

Sheet Frais Export
A1: Pays | B1: Entité représentatrice | C1: Nature frais | D1: Unité | E1: Janvier | F1: Février | G1: Mars | H1: Avril | I1: Mai | J1: Juin | K1: Juillet | L1: Août | M1: Septembre | N1: Octobre | O1: Novembre | P1: Décembre | Q1: Total annuel
A2: Japon | B2: GOODEIS | C2: Transport local | D2: MGA | E2: 11427293 | F2: 9838752 | G2: 9243696 | H2: 10747968 | I2: 10789363 | J2: 10457462 | K2: 10987469 | L2: 10220179 | M2: 9574118 | N2: 12004608 | O2: 9084768 | P2: 9578554 | Q2: =SUM(E2:P2) -> 123954230
A3: Japon | B3: GOODEIS | C3: Transit & documents | D3: MGA | E3: 4530557 | F3: 4968902 | G3: 5327414 | H3: 4980730 | I3: 4089994 | J3: 4411546 | K3: 4846934 | L3: 4787059 | M3: 5164051 | N3: 4821062 | O3: 5515910 | P3: 4988861 | Q3: =SUM(E3:P3) -> 58433020
A4: Japon | B4: GOODEIS | C4: Manutention portuaire | D4: MGA | E4: 6281722 | F4: 6657235 | G4: 5634182 | H4: 6831686 | I4: 6187104 | J4: 6333466 | K4: 5719190 | L4: 6177494 | M4: 7168022 | N4: 6952915 | O4: 6078442 | P4: 7292208 | Q4: =SUM(E4:P4) -> 77313666
A5: Japon | B5: GOODEIS | C5: Fret international | D5: MGA | E5: 32577283 | F5: 38488666 | G5: 37813776 | H5: 32224685 | I5: 37603843 | J5: 38474621 | K5: 35192573 | L5: 41499427 | M5: 31329514 | N5: 38119805 | O5: 38625418 | P5: 35256144 | Q5: =SUM(E5:P5) -> 437205755
A6: Japon | B6: GOODEIS | C6: Assurance transport | D6: MGA | E6: 3029242 | F6: 3885974 | G6: 3900758 | H6: 3849014 | I6: 3908150 | J6: 3593990 | K6: 3866016 | L6: 3976896 | M6: 3200736 | N6: 3655344 | O6: 3931066 | P6: 3255437 | Q6: =SUM(E6:P6) -> 44052623
A7: Japon | B7: GOODEIS | C7: Frais bancaires export | D7: MGA | E7: 2299651 | F7: 2080848 | G7: 2348438 | H7: 2384659 | I7: 2524368 | J7: 2086022 | K7: 2105981 | L7: 2740214 | M7: 2692906 | N7: 2115590 | O7: 2214643 | P7: 2214643 | Q7: =SUM(E7:P7) -> 27807963
A8: Russie | B8: ELINAR | C8: Transport local | D8: MGA | E8: 10470768 | F8: 11263190 | G8: 11623920 | H8: 11368157 | I8: 9697565 | J8: 12549398 | K8: 9983635 | L8: 10039814 | M8: 12048221 | N8: 12388992 | O8: 12605578 | P8: 12287722 | Q8: =SUM(E8:P8) -> 136326960
A9: Russie | B9: ELINAR | C9: Transit & documents | D9: MGA | E9: 5679274 | F9: 5369549 | G9: 5823418 | H9: 5618659 | I9: 5207664 | J9: 4482509 | K9: 4607434 | L9: 5314848 | M9: 5787936 | N9: 4534992 | O9: 4521686 | P9: 5960170 | Q9: =SUM(E9:P9) -> 62908139
A10: Russie | B10: ELINAR | C10: Manutention portuaire | D10: MGA | E10: 6239587 | F10: 6940349 | G10: 7693594 | H10: 6201149 | I10: 6262502 | J10: 7808909 | K10: 7791168 | L10: 6943306 | M10: 7722422 | N10: 7665504 | O10: 7681027 | P10: 8125286 | Q10: =SUM(E10:P10) -> 87074803
A11: Russie | B11: ELINAR | C11: Fret international | D11: MGA | E11: 34299619 | F11: 39499152 | G11: 45613075 | H11: 35086128 | I11: 38354131 | J11: 35464598 | K11: 42850685 | L11: 35874854 | M11: 41327194 | N11: 42778243 | O11: 35562912 | P11: 44766691 | Q11: =SUM(E11:P11) -> 471477282
A12: Russie | B12: ELINAR | C12: Assurance transport | D12: MGA | E12: 3270960 | F12: 3784704 | G12: 3556291 | H12: 4036032 | I12: 4206048 | J12: 3625037 | K12: 3248784 | L12: 3857146 | M12: 3778051 | N12: 4149869 | O12: 4182394 | P12: 3232522 | Q12: =SUM(E12:P12) -> 44927838
A13: Russie | B13: ELINAR | C13: Frais bancaires export | D13: MGA | E13: 2479277 | F13: 2973062 | G13: 2937581 | H13: 2542848 | I13: 2600506 | J13: 2352134 | K13: 2805264 | L13: 2668512 | M13: 2409792 | N13: 2567981 | O13: 2423837 | P13: 2847398 | Q13: =SUM(E13:P13) -> 31608192
... A19: Chine | B19: REPRESENTANT CHINE | C19: Frais bancaires export | D19: MGA | E19: 2185075 | F19: 2279693 | G19: 2003971 | H19: 1869437 | I19: 1848739 | J19: 1897526 | K19: 1893830 | L19: 2350656 | M19: 1866480 | N19: 1881264 | O19: 2232384 | P19: 2466710 | Q19: =SUM(E19:P19) -> 24775765

Sheet Synthese
A1: Indicateur | B1: Unité | C1: Janvier | D1: Février | E1: Mars | F1: Avril | G1: Mai | H1: Juin | I1: Juillet | J1: Août | K1: Septembre | L1: Octobre | M1: Novembre | N1: Décembre | O1: Total annuel
A2: CA export | B2: MGA | C2: =SUMIF(Exportations!$E$10:$E$80,"Chiffre d'affaires MGA",Exportations!$G$10:$G$80) -> 1399520970 | D2: =SUMIF(Exportations!$E$10:$E$80,"Chiffre d'affaires MGA",Exportations!$H$10:$H$80) -> 1388271175 | E2: =SUMIF(Exportations!$E$10:$E$80,"Chiffre d'affaires MGA",Exportations!$I$10:$I$80) -> 1373368915 | F2: =SUMIF(Exportations!$E$10:$E$80,"Chiffre d'affaires MGA",Exportations!$J$10:$J$80) -> 1226711920 | G2: =SUMIF(Exportations!$E$10:$E$80,"Chiffre d'affaires MGA",Exportations!$K$10:$K$80) -> 1348030455 | H2: =SUMIF(Exportations!$E$10:$E$80,"Chiffre d'affaires MGA",Exportations!$L$10:$L$80) -> 1354532225 | I2: =SUMIF(Exportations!$E$10:$E$80,"Chiffre d'affaires MGA",Exportations!$M$10:$M$80) -> 1330905560 | J2: =SUMIF(Exportations!$E$10:$E$80,"Chiffre d'affaires MGA",Exportations!$N$10:$N$80) -> 1411813090 | K2: =SUMIF(Exportations!$E$10:$E$80,"Chiffre d'affaires MGA",Exportations!$O$10:$O$80) -> 1273906740 | L2: =SUMIF(Exportations!$E$10:$E$80,"Chiffre d'affaires MGA",Exportations!$P$10:$P$80) -> 1353034860 | M2: =SUMIF(Exportations!$E$10:$E$80,"Chiffre d'affaires MGA",Exportations!$Q$10:$Q$80) -> 1202432010 | N2: =SUMIF(Exportations!$E$10:$E$80,"Chiffre d'affaires MGA",Exportations!$R$10:$R$80) -> 1393382610 | O2: =SUM(C2:N2) -> 16055910530
A3: Charges exploitation | B3: MGA | C3: =SUMIF(Charges!$A$2:$A$26,"PRODUCTION",Charges!$E$2:$E$26)+SUMIF(Charges!$A$2:$A$26,"ADMINISTRATION",Charges!$E$2:$E$26)-SUMIF(Charges!$B$2:$B$26,"Salaires administratifs",Charges!$E$2:$E$26)+SUMIF(Charges!$A$2:$A$26,"LOGISTIQUE",Charges!$E$2:$E$26)+SUMIF(Charges!$A$2:$A$26,"SECURITE",Charges!$E$2:$E$26)+SUMIF(Charges!$A$2:$A$26,"FISCAL",Charges!$E$2:$E$26)+C5+Amortissements!E13 -> 6.1664351e+08 | D3: =SUMIF(Charges!$A$2:$A$26,"PRODUCTION",Charges!$F$2:$F$26)+SUMIF(Charges!$A$2:$A$26,"ADMINISTRATION",Charges!$F$2:$F$26)-SUMIF(Charges!$B$2:$B$26,"Salaires administratifs",Charges!$F$2:$F$26)+SUMIF(Charges!$A$2:$A$26,"LOGISTIQUE",Charges!$F$2:$F$26)+SUMIF(Charges!$A$2:$A$26,"SECURITE",Charges!$F$2:$F$26)+SUMIF(Charges!$A$2:$A$26,"FISCAL",Charges!$F$2:$F$26)+D5+Amortissements!F13 -> 6.3140787e+08 | E3: =SUMIF(Charges!$A$2:$A$26,"PRODUCTION",Charges!$G$2:$G$26)+SUMIF(Charges!$A$2:$A$26,"ADMINISTRATION",Charges!$G$2:$G$26)-SUMIF(Charges!$B$2:$B$26,"Salaires administratifs",Charges!$G$2:$G$26)+SUMIF(Charges!$A$2:$A$26,"LOGISTIQUE",Charges!$G$2:$G$26)+SUMIF(Charges!$A$2:$A$26,"SECURITE",Charges!$G$2:$G$26)+SUMIF(Charges!$A$2:$A$26,"FISCAL",Charges!$G$2:$G$26)+E5+Amortissements!G13 -> 6.4273457e+08 | F3: =SUMIF(Charges!$A$2:$A$26,"PRODUCTION",Charges!$H$2:$H$26)+SUMIF(Charges!$A$2:$A$26,"ADMINISTRATION",Charges!$H$2:$H$26)-SUMIF(Charges!$B$2:$B$26,"Salaires administratifs",Charges!$H$2:$H$26)+SUMIF(Charges!$A$2:$A$26,"LOGISTIQUE",Charges!$H$2:$H$26)+SUMIF(Charges!$A$2:$A$26,"SECURITE",Charges!$H$2:$H$26)+SUMIF(Charges!$A$2:$A$26,"FISCAL",Charges!$H$2:$H$26)+F5+Amortissements!H13 -> 6.104092e+08 | G3: =SUMIF(Charges!$A$2:$A$26,"PRODUCTION",Charges!$I$2:$I$26)+SUMIF(Charges!$A$2:$A$26,"ADMINISTRATION",Charges!$I$2:$I$26)-SUMIF(Charges!$B$2:$B$26,"Salaires administratifs",Charges!$I$2:$I$26)+SUMIF(Charges!$A$2:$A$26,"LOGISTIQUE",Charges!$I$2:$I$26)+SUMIF(Charges!$A$2:$A$26,"SECURITE",Charges!$I$2:$I$26)+SUMIF(Charges!$A$2:$A$26,"FISCAL",Charges!$I$2:$I$26)+G5+Amortissements!I13 -> 6.4115222e+08 | H3: =SUMIF(Charges!$A$2:$A$26,"PRODUCTION",Charges!$J$2:$J$26)+SUMIF(Charges!$A$2:$A$26,"ADMINISTRATION",Charges!$J$2:$J$26)-SUMIF(Charges!$B$2:$B$26,"Salaires administratifs",Charges!$J$2:$J$26)+SUMIF(Charges!$A$2:$A$26,"LOGISTIQUE",Charges!$J$2:$J$26)+SUMIF(Charges!$A$2:$A$26,"SECURITE",Charges!$J$2:$J$26)+SUMIF(Charges!$A$2:$A$26,"FISCAL",Charges!$J$2:$J$26)+H5+Amortissements!J13 -> 6.1437547e+08 | I3: =SUMIF(Charges!$A$2:$A$26,"PRODUCTION",Charges!$K$2:$K$26)+SUMIF(Charges!$A$2:$A$26,"ADMINISTRATION",Charges!$K$2:$K$26)-SUMIF(Charges!$B$2:$B$26,"Salaires administratifs",Charges!$K$2:$K$26)+SUMIF(Charges!$A$2:$A$26,"LOGISTIQUE",Charges!$K$2:$K$26)+SUMIF(Charges!$A$2:$A$26,"SECURITE",Charges!$K$2:$K$26)+SUMIF(Charges!$A$2:$A$26,"FISCAL",Charges!$K$2:$K$26)+I5+Amortissements!K13 -> 6.2012044e+08 | J3: =SUMIF(Charges!$A$2:$A$26,"PRODUCTION",Charges!$L$2:$L$26)+SUMIF(Charges!$A$2:$A$26,"ADMINISTRATION",Charges!$L$2:$L$26)-SUMIF(Charges!$B$2:$B$26,"Salaires administratifs",Charges!$L$2:$L$26)+SUMIF(Charges!$A$2:$A$26,"LOGISTIQUE",Charges!$L$2:$L$26)+SUMIF(Charges!$A$2:$A$26,"SECURITE",Charges!$L$2:$L$26)+SUMIF(Charges!$A$2:$A$26,"FISCAL",Charges!$L$2:$L$26)+J5+Amortissements!L13 -> 6.2411674e+08 | K3: =SUMIF(Charges!$A$2:$A$26,"PRODUCTION",Charges!$M$2:$M$26)+SUMIF(Charges!$A$2:$A$26,"ADMINISTRATION",Charges!$M$2:$M$26)-SUMIF(Charges!$B$2:$B$26,"Salaires administratifs",Charges!$M$2:$M$26)+SUMIF(Charges!$A$2:$A$26,"LOGISTIQUE",Charges!$M$2:$M$26)+SUMIF(Charges!$A$2:$A$26,"SECURITE",Charges!$M$2:$M$26)+SUMIF(Charges!$A$2:$A$26,"FISCAL",Charges!$M$2:$M$26)+K5+Amortissements!M13 -> 6.0268302e+08 | L3: =SUMIF(Charges!$A$2:$A$26,"PRODUCTION",Charges!$N$2:$N$26)+SUMIF(Charges!$A$2:$A$26,"ADMINISTRATION",Charges!$N$2:$N$26)-SUMIF(Charges!$B$2:$B$26,"Salaires administratifs",Charges!$N$2:$N$26)+SUMIF(Charges!$A$2:$A$26,"LOGISTIQUE",Charges!$N$2:$N$26)+SUMIF(Charges!$A$2:$A$26,"SECURITE",Charges!$N$2:$N$26)+SUMIF(Charges!$A$2:$A$26,"FISCAL",Charges!$N$2:$N$26)+L5+Amortissements!N13 -> 6.1381645e+08 | M3: =SUMIF(Charges!$A$2:$A$26,"PRODUCTION",Charges!$O$2:$O$26)+SUMIF(Charges!$A$2:$A$26,"ADMINISTRATION",Charges!$O$2:$O$26)-SUMIF(Charges!$B$2:$B$26,"Salaires administratifs",Charges!$O$2:$O$26)+SUMIF(Charges!$A$2:$A$26,"LOGISTIQUE",Charges!$O$2:$O$26)+SUMIF(Charges!$A$2:$A$26,"SECURITE",Charges!$O$2:$O$26)+SUMIF(Charges!$A$2:$A$26,"FISCAL",Charges!$O$2:$O$26)+M5+Amortissements!O13 -> 6.3239193e+08 | N3: =SUMIF(Charges!$A$2:$A$26,"PRODUCTION",Charges!$P$2:$P$26)+SUMIF(Charges!$A$2:$A$26,"ADMINISTRATION",Charges!$P$2:$P$26)-SUMIF(Charges!$B$2:$B$26,"Salaires administratifs",Charges!$P$2:$P$26)+SUMIF(Charges!$A$2:$A$26,"LOGISTIQUE",Charges!$P$2:$P$26)+SUMIF(Charges!$A$2:$A$26,"SECURITE",Charges!$P$2:$P$26)+SUMIF(Charges!$A$2:$A$26,"FISCAL",Charges!$P$2:$P$26)+N5+Amortissements!P13 -> 6.2719674e+08 | O3: =SUM(C3:N3) -> 7.4770482e+09
A4: Frais export | B4: MGA | C4: =SUM('Frais Export'!E2:E50) -> 179664779 | D4: =SUM('Frais Export'!F2:F50) -> 194350463 | E4: =SUM('Frais Export'!G2:G50) -> 200183490 | F4: =SUM('Frais Export'!H2:H50) -> 179593076 | G4: =SUM('Frais Export'!I2:I50) -> 192380495 | H4: =SUM('Frais Export'!J2:J50) -> 190250120 | I4: =SUM('Frais Export'!K2:K50) -> 185474150 | J4: =SUM('Frais Export'!L2:L50) -> 195120709 | ... N4: =SUM('Frais Export'!P2:P50) -> 198934243 | O4: =SUM(C4:N4) -> 2294149331
A5: Masse salariale | B5: MGA | C5: =SUM(Employes!$I$2:$I$100) -> 252921620 | D5: =SUM(Employes!$I$2:$I$100) -> 252921620 | E5: =SUM(Employes!$I$2:$I$100) -> 252921620 | F5: =SUM(Employes!$I$2:$I$100) -> 252921620 | G5: =SUM(Employes!$I$2:$I$100) -> 252921620 | H5: =SUM(Employes!$I$2:$I$100) -> 252921620 | I5: =SUM(Employes!$I$2:$I$100) -> 252921620 | J5: =SUM(Employes!$I$2:$I$100) -> 252921620 | ... N5: =SUM(Employes!$I$2:$I$100) -> 252921620 | O5: =SUM(C5:N5) -> 3035059440
A6: Résultat opérationnel | B6: MGA | C6: =C2-C3-C4 -> 6.0321268e+08 | D6: =D2-D3-D4 -> 5.6251284e+08 | E6: =E2-E3-E4 -> 5.3045085e+08 | F6: =F2-F3-F4 -> 4.3670964e+08 | G6: =G2-G3-G4 -> 5.1449774e+08 | H6: =H2-H3-H4 -> 5.4990663e+08 | I6: =I2-I3-I4 -> 5.2531097e+08 | J6: =J2-J3-J4 -> 5.9257564e+08 | ... N6: =N2-N3-N4 -> 5.6725162e+08 | O6: =SUM(C6:N6) -> 6.284713e+09
A7: Marge opérationnelle | B7: % | C7: =IFERROR(C6/C2,0) -> 0.43101368 | D7: =IFERROR(D6/D2,0) -> 0.40518945 | E7: =IFERROR(E6/E2,0) -> 0.38624061 | F7: =IFERROR(F6/F2,0) -> 0.35600016 | G7: =IFERROR(G6/G2,0) -> 0.38166625 | H7: =IFERROR(H6/H2,0) -> 0.4059753 | I7: =IFERROR(I6/I2,0) -> 0.39470191 | J7: =IFERROR(J6/J2,0) -> 0.41972669 | ... O7: =IFERROR(O6/O2,0) -> 0.39142676

Sheet CR
A1: COMPTE DE RÉSULTAT PAR NATURE — SOMIDA 2019
A2: Montants en MGA
A4: Rubriques | B4: Janvier | C4: Février | D4: Mars | E4: Avril | F4: Mai | G4: Juin | H4: Juillet | I4: Août | J4: Septembre | K4: Octobre | L4: Novembre | M4: Décembre | N4: Total annuel
A5: Chiffre d'affaires | B5: =IF(Synthese!C2="",0,Synthese!C2) -> 1399520970 | C5: =IF(Synthese!D2="",0,Synthese!D2) -> 1388271175 | D5: =IF(Synthese!E2="",0,Synthese!E2) -> 1373368915 | E5: =IF(Synthese!F2="",0,Synthese!F2) -> 1226711920 | F5: =IF(Synthese!G2="",0,Synthese!G2) -> 1348030455 | G5: =IF(Synthese!H2="",0,Synthese!H2) -> 1354532225 | H5: =IF(Synthese!I2="",0,Synthese!I2) -> 1330905560 | I5: =IF(Synthese!J2="",0,Synthese!J2) -> 1411813090 | ... M5: =IF(Synthese!N2="",0,Synthese!N2) -> 1393382610 | N5: =SUM(B5:M5) -> 16055910530
A6: Production stockée | B6: =0 -> 0 | C6: =0 -> 0 | D6: =0 -> 0 | E6: =0 -> 0 | F6: =0 -> 0 | G6: =0 -> 0 | H6: =0 -> 0 | I6: =0 -> 0 | ... M6: =0 -> 0 | N6: =SUM(B6:M6) -> 0
A7: Production immobilisée | B7: =0 -> 0 | C7: =0 -> 0 | D7: =0 -> 0 | E7: =0 -> 0 | F7: =0 -> 0 | G7: =0 -> 0 | H7: =0 -> 0 | I7: =0 -> 0 | ... M7: =0 -> 0 | N7: =SUM(B7:M7) -> 0
A8: I. PRODUCTION DE L'EXERCICE | B8: =SUM(B5:B7) -> 1399520970 | C8: =SUM(C5:C7) -> 1388271175 | D8: =SUM(D5:D7) -> 1373368915 | E8: =SUM(E5:E7) -> 1226711920 | F8: =SUM(F5:F7) -> 1348030455 | G8: =SUM(G5:G7) -> 1354532225 | H8: =SUM(H5:H7) -> 1330905560 | I8: =SUM(I5:I7) -> 1411813090 | ... M8: =SUM(M5:M7) -> 1393382610 | N8: =SUM(B8:M8) -> 16055910530
A9: Achats consommés / charges directes de production | B9: =SUMIF(Charges!$A$2:$A$26,"PRODUCTION",Charges!$E$2:$E$26) -> 250032860 | C9: =SUMIF(Charges!$A$2:$A$26,"PRODUCTION",Charges!$F$2:$F$26) -> 260452500 | D9: =SUMIF(Charges!$A$2:$A$26,"PRODUCTION",Charges!$G$2:$G$26) -> 268446640 | E9: =SUMIF(Charges!$A$2:$A$26,"PRODUCTION",Charges!$H$2:$H$26) -> 242438350 | F9: =SUMIF(Charges!$A$2:$A$26,"PRODUCTION",Charges!$I$2:$I$26) -> 271314890 | G9: =SUMIF(Charges!$A$2:$A$26,"PRODUCTION",Charges!$J$2:$J$26) -> 243530980 | H9: =SUMIF(Charges!$A$2:$A$26,"PRODUCTION",Charges!$K$2:$K$26) -> 254881550 | I9: =SUMIF(Charges!$A$2:$A$26,"PRODUCTION",Charges!$L$2:$L$26) -> 254871540 | J9: =SUMIF(Charges!$A$2:$A$26,"PRODUCTION",Charges!$M$2:$M$26) -> 234834600 | K9: =SUMIF(Charges!$A$2:$A$26,"PRODUCTION",Charges!$N$2:$N$26) -> 249797240 | L9: =SUMIF(Charges!$A$2:$A$26,"PRODUCTION",Charges!$O$2:$O$26) -> 269434550 | M9: =SUMIF(Charges!$A$2:$A$26,"PRODUCTION",Charges!$P$2:$P$26) -> 254635920 | N9: =SUM(B9:M9) -> 3054671620
A10: Services extérieurs et autres consommations | B10: =SUMIF(Charges!$A$2:$A$26,"ADMINISTRATION",Charges!$E$2:$E$26)-SUMIF(Charges!$B$2:$B$26,"Salaires administratifs",Charges!$E$2:$E$26)+SUMIF(Charges!$A$2:$A$26,"LOGISTIQUE",Charges!$E$2:$E$26)+SUMIF(Charges!$A$2:$A$26,"SECURITE",Charges!$E$2:$E$26)+SUM('Frais Export'!$E$2:$E$50) -> 267793589 | C10: =SUMIF(Charges!$A$2:$A$26,"ADMINISTRATION",Charges!$F$2:$F$26)-SUMIF(Charges!$B$2:$B$26,"Salaires administratifs",Charges!$F$2:$F$26)+SUMIF(Charges!$A$2:$A$26,"LOGISTIQUE",Charges!$F$2:$F$26)+SUMIF(Charges!$A$2:$A$26,"SECURITE",Charges!$F$2:$F$26)+SUM('Frais Export'!$F$2:$F$50) -> 280448013 | D10: =SUMIF(Charges!$A$2:$A$26,"ADMINISTRATION",Charges!$G$2:$G$26)-SUMIF(Charges!$B$2:$B$26,"Salaires administratifs",Charges!$G$2:$G$26)+SUMIF(Charges!$A$2:$A$26,"LOGISTIQUE",Charges!$G$2:$G$26)+SUMIF(Charges!$A$2:$A$26,"SECURITE",Charges!$G$2:$G$26)+SUM('Frais Export'!$G$2:$G$50) -> 290739340 | E10: =SUMIF(Charges!$A$2:$A$26,"ADMINISTRATION",Charges!$H$2:$H$26)-SUMIF(Charges!$B$2:$B$26,"Salaires administratifs",Charges!$H$2:$H$26)+SUMIF(Charges!$A$2:$A$26,"LOGISTIQUE",Charges!$H$2:$H$26)+SUMIF(Charges!$A$2:$A$26,"SECURITE",Charges!$H$2:$H$26)+SUM('Frais Export'!$H$2:$H$50) -> 265296386 | F10: =SUMIF(Charges!$A$2:$A$26,"ADMINISTRATION",Charges!$I$2:$I$26)-SUMIF(Charges!$B$2:$B$26,"Salaires administratifs",Charges!$I$2:$I$26)+SUMIF(Charges!$A$2:$A$26,"LOGISTIQUE",Charges!$I$2:$I$26)+SUMIF(Charges!$A$2:$A$26,"SECURITE",Charges!$I$2:$I$26)+SUM('Frais Export'!$I$2:$I$50) -> 278263215 | G10: =SUMIF(Charges!$A$2:$A$26,"ADMINISTRATION",Charges!$J$2:$J$26)-SUMIF(Charges!$B$2:$B$26,"Salaires administratifs",Charges!$J$2:$J$26)+SUMIF(Charges!$A$2:$A$26,"LOGISTIQUE",Charges!$J$2:$J$26)+SUMIF(Charges!$A$2:$A$26,"SECURITE",Charges!$J$2:$J$26)+SUM('Frais Export'!$J$2:$J$50) -> 280074470 | H10: =SUMIF(Charges!$A$2:$A$26,"ADMINISTRATION",Charges!$K$2:$K$26)-SUMIF(Charges!$B$2:$B$26,"Salaires administratifs",Charges!$K$2:$K$26)+SUMIF(Charges!$A$2:$A$26,"LOGISTIQUE",Charges!$K$2:$K$26)+SUMIF(Charges!$A$2:$A$26,"SECURITE",Charges!$K$2:$K$26)+SUM('Frais Export'!$K$2:$K$50) -> 266505870 | I10: =SUMIF(Charges!$A$2:$A$26,"ADMINISTRATION",Charges!$L$2:$L$26)-SUMIF(Charges!$B$2:$B$26,"Salaires administratifs",Charges!$L$2:$L$26)+SUMIF(Charges!$A$2:$A$26,"LOGISTIQUE",Charges!$L$2:$L$26)+SUMIF(Charges!$A$2:$A$26,"SECURITE",Charges!$L$2:$L$26)+SUM('Frais Export'!$L$2:$L$50) -> 282924579 | J10: =SUMIF(Charges!$A$2:$A$26,"ADMINISTRATION",Charges!$M$2:$M$26)-SUMIF(Charges!$B$2:$B$26,"Salaires administratifs",Charges!$M$2:$M$26)+SUMIF(Charges!$A$2:$A$26,"LOGISTIQUE",Charges!$M$2:$M$26)+SUMIF(Charges!$A$2:$A$26,"SECURITE",Charges!$M$2:$M$26)+SUM('Frais Export'!$M$2:$M$50) -> 278569368 | K10: =SUMIF(Charges!$A$2:$A$26,"ADMINISTRATION",Charges!$N$2:$N$26)-SUMIF(Charges!$B$2:$B$26,"Salaires administratifs",Charges!$N$2:$N$26)+SUMIF(Charges!$A$2:$A$26,"LOGISTIQUE",Charges!$N$2:$N$26)+SUMIF(Charges!$A$2:$A$26,"SECURITE",Charges!$N$2:$N$26)+SUM('Frais Export'!$N$2:$N$50) -> 282225574 | L10: =SUMIF(Charges!$A$2:$A$26,"ADMINISTRATION",Charges!$O$2:$O$26)-SUMIF(Charges!$B$2:$B$26,"Salaires administratifs",Charges!$O$2:$O$26)+SUMIF(Charges!$A$2:$A$26,"LOGISTIQUE",Charges!$O$2:$O$26)+SUMIF(Charges!$A$2:$A$26,"SECURITE",Charges!$O$2:$O$26)+SUM('Frais Export'!$O$2:$O$50) -> 269518574 | M10: =SUMIF(Charges!$A$2:$A$26,"ADMINISTRATION",Charges!$P$2:$P$26)-SUMIF(Charges!$B$2:$B$26,"Salaires administratifs",Charges!$P$2:$P$26)+SUMIF(Charges!$A$2:$A$26,"LOGISTIQUE",Charges!$P$2:$P$26)+SUMIF(Charges!$A$2:$A$26,"SECURITE",Charges!$P$2:$P$26)+SUM('Frais Export'!$P$2:$P$50) -> 286806643 | N10: =SUM(B10:M10) -> 3329165621
A11: II. CONSOMMATION DE L'EXERCICE | B11: =SUM(B9:B10) -> 517826449 | C11: =SUM(C9:C10) -> 540900513 | D11: =SUM(D9:D10) -> 559185980 | E11: =SUM(E9:E10) -> 507734736 | F11: =SUM(F9:F10) -> 549578105 | G11: =SUM(G9:G10) -> 523605450 | H11: =SUM(H9:H10) -> 521387420 | I11: =SUM(I9:I10) -> 537796119 | ... M11: =SUM(M9:M10) -> 541442563 | N11: =SUM(B11:M11) -> 6383837241
A12: III. VALEUR AJOUTÉE D'EXPLOITATION (I-II) | B12: =B8-B11 -> 881694521 | C12: =C8-C11 -> 847370662 | D12: =D8-D11 -> 814182935 | E12: =E8-E11 -> 718977184 | F12: =F8-F11 -> 798452350 | G12: =G8-G11 -> 830926775 | H12: =H8-H11 -> 809518140 | I12: =I8-I11 -> 874016971 | ... M12: =M8-M11 -> 851940047 | N12: =SUM(B12:M12) -> 9672073289
A13: Subventions d'exploitation | B13: =0 -> 0 | C13: =0 -> 0 | D13: =0 -> 0 | E13: =0 -> 0 | F13: =0 -> 0 | G13: =0 -> 0 | H13: =0 -> 0 | I13: =0 -> 0 | ... M13: =0 -> 0 | N13: =SUM(B13:M13) -> 0
A14: Impôts, taxes et versements assimilés | B14: =SUMIF(Charges!$A$2:$A$26,"FISCAL",Charges!$E$2:$E$26) -> 21021770 | C14: =SUMIF(Charges!$A$2:$A$26,"FISCAL",Charges!$F$2:$F$26) -> 23114630 | D14: =SUMIF(Charges!$A$2:$A$26,"FISCAL",Charges!$G$2:$G$26) -> 21988890 | E14: =SUMIF(Charges!$A$2:$A$26,"FISCAL",Charges!$H$2:$H$26) -> 20524350 | F14: =SUMIF(Charges!$A$2:$A$26,"FISCAL",Charges!$I$2:$I$26) -> 22211420 | G14: =SUMIF(Charges!$A$2:$A$26,"FISCAL",Charges!$J$2:$J$26) -> 19276950 | H14: =SUMIF(Charges!$A$2:$A$26,"FISCAL",Charges!$K$2:$K$26) -> 22463980 | I14: =SUMIF(Charges!$A$2:$A$26,"FISCAL",Charges!$L$2:$L$26) -> 19698140 | J14: =SUMIF(Charges!$A$2:$A$26,"FISCAL",Charges!$M$2:$M$26) -> 18851910 | K14: =SUMIF(Charges!$A$2:$A$26,"FISCAL",Charges!$N$2:$N$26) -> 19140660 | L14: =SUMIF(Charges!$A$2:$A$26,"FISCAL",Charges!$O$2:$O$26) -> 19487160 | M14: =SUMIF(Charges!$A$2:$A$26,"FISCAL",Charges!$P$2:$P$26) -> 22945230 | N14: =SUM(B14:M14) -> 250725090
A15: Charges de personnel | B15: =IF(Synthese!C5="",0,Synthese!C5) -> 252921620 | C15: =IF(Synthese!D5="",0,Synthese!D5) -> 252921620 | D15: =IF(Synthese!E5="",0,Synthese!E5) -> 252921620 | E15: =IF(Synthese!F5="",0,Synthese!F5) -> 252921620 | F15: =IF(Synthese!G5="",0,Synthese!G5) -> 252921620 | G15: =IF(Synthese!H5="",0,Synthese!H5) -> 252921620 | H15: =IF(Synthese!I5="",0,Synthese!I5) -> 252921620 | I15: =IF(Synthese!J5="",0,Synthese!J5) -> 252921620 | ... M15: =IF(Synthese!N5="",0,Synthese!N5) -> 252921620 | N15: =SUM(B15:M15) -> 3035059440
A16: IV. EXCÉDENT BRUT D'EXPLOITATION | B16: =B12+B13-B14-B15 -> 607751131 | C16: =C12+C13-C14-C15 -> 571334412 | D16: =D12+D13-D14-D15 -> 539272425 | E16: =E12+E13-E14-E15 -> 445531214 | F16: =F12+F13-F14-F15 -> 523319310 | G16: =G12+G13-G14-G15 -> 558728205 | H16: =H12+H13-H14-H15 -> 534132540 | I16: =I12+I13-I14-I15 -> 601397211 | ... M16: =M12+M13-M14-M15 -> 576073197 | N16: =SUM(B16:M16) -> 6386288759
A17: Autres produits opérationnels | B17: =0 -> 0 | C17: =0 -> 0 | D17: =0 -> 0 | E17: =0 -> 0 | F17: =0 -> 0 | G17: =0 -> 0 | H17: =0 -> 0 | I17: =0 -> 0 | ... M17: =0 -> 0 | N17: =SUM(B17:M17) -> 0
A18: Autres charges opérationnelles | B18: =0 -> 0 | C18: =0 -> 0 | D18: =0 -> 0 | E18: =0 -> 0 | F18: =0 -> 0 | G18: =0 -> 0 | H18: =0 -> 0 | I18: =0 -> 0 | ... M18: =0 -> 0 | N18: =SUM(B18:M18) -> 0
A19: Dotations aux amortissements | B19: =Amortissements!E13 -> 4538449.8 | C19: =Amortissements!F13 -> 8821574.8 | D19: =Amortissements!G13 -> 8821574.8 | E19: =Amortissements!H13 -> 8821574.8 | F19: =Amortissements!I13 -> 8821574.8 | G19: =Amortissements!J13 -> 8821574.8 | H19: =Amortissements!K13 -> 8821574.8 | I19: =Amortissements!L13 -> 8821574.8 | ... M19: =Amortissements!P13 -> 8821574.8 | N19: =SUM(B19:M19) -> 1.0157577e+08
A20: Provisions et pertes de valeur | B20: =0 -> 0 | C20: =0 -> 0 | D20: =0 -> 0 | E20: =0 -> 0 | F20: =0 -> 0 | G20: =0 -> 0 | H20: =0 -> 0 | I20: =0 -> 0 | ... M20: =0 -> 0 | N20: =SUM(B20:M20) -> 0
A21: Reprises sur provisions et pertes de valeur | B21: =0 -> 0 | C21: =0 -> 0 | D21: =0 -> 0 | E21: =0 -> 0 | F21: =0 -> 0 | G21: =0 -> 0 | H21: =0 -> 0 | I21: =0 -> 0 | ... M21: =0 -> 0 | N21: =SUM(B21:M21) -> 0
A22: V. RÉSULTAT OPÉRATIONNEL | B22: =B16+B17-B18-B19-B20+B21 -> 6.0321268e+08 | C22: =C16+C17-C18-C19-C20+C21 -> 5.6251284e+08 | D22: =D16+D17-D18-D19-D20+D21 -> 5.3045085e+08 | E22: =E16+E17-E18-E19-E20+E21 -> 4.3670964e+08 | F22: =F16+F17-F18-F19-F20+F21 -> 5.1449774e+08 | G22: =G16+G17-G18-G19-G20+G21 -> 5.4990663e+08 | H22: =H16+H17-H18-H19-H20+H21 -> 5.2531097e+08 | I22: =I16+I17-I18-I19-I20+I21 -> 5.9257564e+08 | ... M22: =M16+M17-M18-M19-M20+M21 -> 5.6725162e+08 | N22: =SUM(B22:M22) -> 6.284713e+09
A23: Produits financiers | B23: =0 -> 0 | C23: =0 -> 0 | D23: =0 -> 0 | E23: =0 -> 0 | F23: =0 -> 0 | G23: =0 -> 0 | H23: =0 -> 0 | I23: =0 -> 0 | ... M23: =0 -> 0 | N23: =SUM(B23:M23) -> 0
A24: Charges financières | B24: =SUMIF(Charges!$A$2:$A$26,"FINANCE",Charges!$E$2:$E$26) -> 8032640 | C24: =SUMIF(Charges!$A$2:$A$26,"FINANCE",Charges!$F$2:$F$26) -> 7614530 | D24: =SUMIF(Charges!$A$2:$A$26,"FINANCE",Charges!$G$2:$G$26) -> 9497950 | E24: =SUMIF(Charges!$A$2:$A$26,"FINANCE",Charges!$H$2:$H$26) -> 9240000 | F24: =SUMIF(Charges!$A$2:$A$26,"FINANCE",Charges!$I$2:$I$26) -> 7983360 | G24: =SUMIF(Charges!$A$2:$A$26,"FINANCE",Charges!$J$2:$J$26) -> 9360120 | H24: =SUMIF(Charges!$A$2:$A$26,"FINANCE",Charges!$K$2:$K$26) -> 9524900 | I24: =SUMIF(Charges!$A$2:$A$26,"FINANCE",Charges!$L$2:$L$26) -> 7629160 | J24: =SUMIF(Charges!$A$2:$A$26,"FINANCE",Charges!$M$2:$M$26) -> 8237460 | K24: =SUMIF(Charges!$A$2:$A$26,"FINANCE",Charges!$N$2:$N$26) -> 7813960 | L24: =SUMIF(Charges!$A$2:$A$26,"FINANCE",Charges!$O$2:$O$26) -> 8216670 | M24: =SUMIF(Charges!$A$2:$A$26,"FINANCE",Charges!$P$2:$P$26) -> 9113720 | N24: =SUM(B24:M24) -> 102264470
A25: VI. RÉSULTAT FINANCIER | B25: =B23-B24 -> -8032640 | C25: =C23-C24 -> -7614530 | D25: =D23-D24 -> -9497950 | E25: =E23-E24 -> -9240000 | F25: =F23-F24 -> -7983360 | G25: =G23-G24 -> -9360120 | H25: =H23-H24 -> -9524900 | I25: =I23-I24 -> -7629160 | ... M25: =M23-M24 -> -9113720 | N25: =SUM(B25:M25) -> -102264470
A26: VII. RÉSULTAT AVANT IMPÔTS (V+VI) | B26: =B22+B25 -> 5.9518004e+08 | C26: =C22+C25 -> 5.5489831e+08 | D26: =D22+D25 -> 5.209529e+08 | E26: =E22+E25 -> 4.2746964e+08 | F26: =F22+F25 -> 5.0651438e+08 | G26: =G22+G25 -> 5.4054651e+08 | H26: =H22+H25 -> 5.1578607e+08 | I26: =I22+I25 -> 5.8494648e+08 | ... M26: =M22+M25 -> 5.581379e+08 | N26: =SUM(B26:M26) -> 6.1824485e+09
A27: Impôt exigible sur les résultats (20%) | B27: =IF(B26>0,B26*20%,0) -> 1.1903601e+08 | C27: =IF(C26>0,C26*20%,0) -> 1.1097966e+08 | D27: =IF(D26>0,D26*20%,0) -> 1.0419058e+08 | E27: =IF(E26>0,E26*20%,0) -> 85493928 | F27: =IF(F26>0,F26*20%,0) -> 1.0130288e+08 | G27: =IF(G26>0,G26*20%,0) -> 1.081093e+08 | H27: =IF(H26>0,H26*20%,0) -> 1.0315721e+08 | I27: =IF(I26>0,I26*20%,0) -> 1.169893e+08 | ... M27: =IF(M26>0,M26*20%,0) -> 1.1162758e+08 | N27: =SUM(B27:M27) -> 1.2364897e+09
A28: Impôts différés | B28: =0 -> 0 | C28: =0 -> 0 | D28: =0 -> 0 | E28: =0 -> 0 | F28: =0 -> 0 | G28: =0 -> 0 | H28: =0 -> 0 | I28: =0 -> 0 | ... M28: =0 -> 0 | N28: =SUM(B28:M28) -> 0
A29: VIII. RÉSULTAT NET DES ACTIVITÉS ORDINAIRES | B29: =B26-B27-B28 -> 4.7614403e+08 | C29: =C26-C27-C28 -> 4.4391865e+08 | D29: =D26-D27-D28 -> 4.1676232e+08 | E29: =E26-E27-E28 -> 3.4197571e+08 | F29: =F26-F27-F28 -> 4.052115e+08 | G29: =G26-G27-G28 -> 4.3243721e+08 | H29: =H26-H27-H28 -> 4.1262885e+08 | I29: =I26-I27-I28 -> 4.6795718e+08 | ... M29: =M26-M27-M28 -> 4.4651032e+08 | N29: =SUM(B29:M29) -> 4.9459588e+09
A30: Éléments extraordinaires - produits | B30: =0 -> 0 | C30: =0 -> 0 | D30: =0 -> 0 | E30: =0 -> 0 | F30: =0 -> 0 | G30: =0 -> 0 | H30: =0 -> 0 | I30: =0 -> 0 | ... M30: =0 -> 0 | N30: =SUM(B30:M30) -> 0
A31: Éléments extraordinaires - charges | B31: =0 -> 0 | C31: =0 -> 0 | D31: =0 -> 0 | E31: =0 -> 0 | F31: =0 -> 0 | G31: =0 -> 0 | H31: =0 -> 0 | I31: =0 -> 0 | ... M31: =0 -> 0 | N31: =SUM(B31:M31) -> 0
A32: IX. RÉSULTAT EXTRAORDINAIRE | B32: =B30-B31 -> 0 | C32: =C30-C31 -> 0 | D32: =D30-D31 -> 0 | E32: =E30-E31 -> 0 | F32: =F30-F31 -> 0 | G32: =G30-G31 -> 0 | H32: =H30-H31 -> 0 | I32: =I30-I31 -> 0 | ... M32: =M30-M31 -> 0 | N32: =SUM(B32:M32) -> 0
A33: X. RÉSULTAT NET DE L'EXERCICE | B33: =B29+B32 -> 4.7614403e+08 | C33: =C29+C32 -> 4.4391865e+08 | D33: =D29+D32 -> 4.1676232e+08 | E33: =E29+E32 -> 3.4197571e+08 | F33: =F29+F32 -> 4.052115e+08 | G33: =G29+G32 -> 4.3243721e+08 | H33: =H29+H32 -> 4.1262885e+08 | I33: =I29+I32 -> 4.6795718e+08 | ... M33: =M29+M32 -> 4.4651032e+08 | N33: =SUM(B33:M33) -> 4.9459588e+09
A34: Marge nette | B34: =IFERROR(B33/B5,0) -> 0.34021929 | C34: =IFERROR(C33/C5,0) -> 0.31976364 | D34: =IFERROR(D33/D5,0) -> 0.30345985 | E34: =IFERROR(E33/E5,0) -> 0.27877426 | F34: =IFERROR(F33/F5,0) -> 0.30059521 | G34: =IFERROR(G33/G5,0) -> 0.31925206 | H34: =IFERROR(H33/H5,0) -> 0.31003616 | I34: =IFERROR(I33/I5,0) -> 0.33145831 | ... N34: =IFERROR(N33/N5,0) -> 0.30804599

Sheet Amortissements
A1: Catégorie | B1: Nature | C1: Périmètre général | D1: Unité | E1: Janvier | F1: Février | G1: Mars | H1: Avril | I1: Mai | J1: Juin | K1: Juillet | L1: Août | M1: Septembre | N1: Octobre | O1: Novembre | P1: Décembre | Q1: Total annuel
A2: AMORTISSEMENT | B2: DOT.AMORT.MAT & OUTILLAGE | D2: MGA | E2: 1028335.7 | F2: 1028335.7 | G2: 1028335.7 | H2: 1028335.7 | I2: 1028335.7 | J2: 1028335.7 | K2: 1028335.7 | L2: 1028335.7 | M2: 1028335.7 | N2: 1028335.7 | O2: 1028335.7 | P2: 1028335.7 | Q2: 12340028
A3: AMORTISSEMENT | B3: DOT.AMORT.VEHICULE UTILITAIRE | D3: MGA | E3: 1733900.4 | F3: 1733900.4 | G3: 1733900.4 | H3: 1733900.4 | I3: 1733900.4 | J3: 1733900.4 | K3: 1733900.4 | L3: 1733900.4 | M3: 1733900.4 | N3: 1733900.4 | O3: 1733900.4 | P3: 1733900.4 | Q3: 20806805
A4: AMORTISSEMENT | B4: Autres immobilisations 1 | D4: MGA | E4: 0 | F4: 256666.67 | G4: 256666.67 | H4: 256666.67 | I4: 256666.67 | J4: 256666.67 | K4: 256666.67 | L4: 256666.67 | M4: 256666.67 | N4: 256666.67 | O4: 256666.67 | P4: 256666.67 | Q4: 2823333.3
A5: AMORTISSEMENT | B5: DOT.AMORT Réparations toitures | D5: MGA | E5: 0 | F5: 3850000 | G5: 3850000 | H5: 3850000 | I5: 3850000 | J5: 3850000 | K5: 3850000 | L5: 3850000 | M5: 3850000 | N5: 3850000 | O5: 3850000 | P5: 3850000 | Q5: 42350000
A6: AMORTISSEMENT | B6: Autres immobilisations 2 | D6: MGA | E6: 0 | F6: 64166.667 | G6: 64166.667 | H6: 64166.667 | I6: 64166.667 | J6: 64166.667 | K6: 64166.667 | L6: 64166.667 | M6: 64166.667 | N6: 64166.667 | O6: 64166.667 | P6: 64166.667 | Q6: 705833.33
A7: AMORTISSEMENT | B7: DOT.AMORT.AGENC AMENAG CONSTRUC | D7: MGA | E7: 0 | F7: 0 | G7: 0 | H7: 0 | I7: 0 | J7: 0 | K7: 0 | L7: 0 | M7: 0 | N7: 0 | O7: 0 | P7: 0 | Q7: 0
A8: AMORTISSEMENT | B8: DOT.AMORT.AUTRES INSTALLATIONS | D8: MGA | E8: 9112.3436 | F8: 9112.3436 | G8: 9112.3436 | H8: 9112.3436 | I8: 9112.3436 | J8: 9112.3436 | K8: 9112.3436 | L8: 9112.3436 | M8: 9112.3436 | N8: 9112.3436 | O8: 9112.3436 | P8: 9112.3436 | Q8: 109348.12
A9: AMORTISSEMENT | B9: DOT.AMORT.MATERIEL DE BUREAU | D9: MGA | E9: 1438671.3 | F9: 1438671.3 | G9: 1438671.3 | H9: 1438671.3 | I9: 1438671.3 | J9: 1438671.3 | K9: 1438671.3 | L9: 1438671.3 | M9: 1438671.3 | N9: 1438671.3 | O9: 1438671.3 | P9: 1438671.3 | Q9: 17264055
A10: AMORTISSEMENT | B10: DOT.AMORT.MATERIEL INFORMATIQUE | D10: MGA | E10: 123888.98 | F10: 123888.98 | G10: 123888.98 | H10: 123888.98 | I10: 123888.98 | J10: 123888.98 | K10: 123888.98 | L10: 123888.98 | M10: 123888.98 | N10: 123888.98 | O10: 123888.98 | P10: 123888.98 | Q10: 1486667.8
A11: AMORTISSEMENT | B11: DOT.AMORT.MAT.& MOB.DE LOGEMENT | D11: MGA | E11: 204541.08 | F11: 204541.08 | G11: 204541.08 | H11: 204541.08 | I11: 204541.08 | J11: 204541.08 | K11: 204541.08 | L11: 204541.08 | M11: 204541.08 | N11: 204541.08 | O11: 204541.08 | P11: 204541.08 | Q11: 2454493
A12: AMORTISSEMENT | B12: Autres amortissements | D12: MGA | E12: 0 | F12: 112291.67 | G12: 112291.67 | H12: 112291.67 | I12: 112291.67 | J12: 112291.67 | K12: 112291.67 | L12: 112291.67 | M12: 112291.67 | N12: 112291.67 | O12: 112291.67 | P12: 112291.67 | Q12: 1235208.3
A13: AMORTISSEMENT | B13: TOTAL DOTATIONS AUX AMORTISSEMENTS | D13: MGA | E13: =SUM(E2:E12) -> 4538449.8 | F13: =SUM(F2:F12) -> 8821574.8 | G13: =SUM(G2:G12) -> 8821574.8 | H13: =SUM(H2:H12) -> 8821574.8 | I13: =SUM(I2:I12) -> 8821574.8 | J13: =SUM(J2:J12) -> 8821574.8 | K13: =SUM(K2:K12) -> 8821574.8 | L13: =SUM(L2:L12) -> 8821574.8 | ... P13: =SUM(P2:P12) -> 8821574.8 | Q13: =SUM(E13:P13) -> 1.0157577e+08
